<?xml version="1.0" ?>
<robot name="R_inspire">

    <link name="base_link"/>
    <joint name="R_gripper_base_joint" type="fixed">
      <origin
      xyz="0 0 0.03"
      rpy="3.1415926 0 1.5" />
      <parent link="base_link"/>
      <child link="R_flange"/>
    </joint>


    <link name="R_flange">
      <visual>
        <origin xyz="0 0 0" rpy="0 0 0"/>
        <geometry>
          <mesh filename="file:///home/iwatts/Documents/tang/VisionRobot/nv8arm/foxy/nv6_ws/src/moveit_resources_rrr_description/meshes_inspire/flange.STL" scale="0.001 0.001 0.001"/>
        </geometry>
        <material
          name="">
          <color
            rgba="1 1 1 1" />
        </material>
      </visual>
      <collision>
        <origin xyz="0 0 0" rpy="0 0 0"/>
        <geometry>
          <mesh filename="file:///home/iwatts/Documents/tang/VisionRobot/nv8arm/foxy/nv6_ws/src/moveit_resources_rrr_description/meshes_inspire/flange.STL" scale="0.001 0.001 0.001"/>
        </geometry>
      </collision>
      <inertial>
        <origin
          xyz="0 0 0"
          rpy="0 0 0" />
        <mass
          value="1.0372398E-01" />
        <inertia
          ixx="8.6985265E-05"
          ixy="0"
          ixz="2.7728445E-07"
          iyy="8.7567207E-05"
          iyz="6.8674339E-07"
          izz="7.4487068E-05"/>
      </inertial>
    </link>

    <joint 
      name="R_base_link_joint" 
      type="fixed">
      <origin
      xyz="0 0 0"
      rpy="1.570796 0 0" />
      <parent link="R_flange"/>
      <child link="R_hand_base_link"/>
    </joint>

  <link
    name="R_hand_base_link">
    <inertial>
      <origin
        xyz="-0.0025264 -0.066047 0.0019598"
        rpy="0 0 0" />
      <mass
        value="0.14143" />
      <inertia
        ixx="0.00012281"
        ixy="2.1711E-06"
        ixz="1.7709E-06"
        iyy="8.3832E-05"
        iyz="-1.6551E-06"
        izz="7.6663E-05" />
    </inertial>
    <visual>
      <origin
        xyz="0 0 0"
        rpy="0 0 0" />
      <geometry>
        <mesh
          filename="file:///home/iwatts/Documents/tang/VisionRobot/nv8arm/foxy/nv6_ws/src/moveit_resources_rrr_description/meshes_inspire/base_link.STL" />
      </geometry>
      <material
        name="">
        <color
          rgba="1 1 1 1" />
      </material>
    </visual>
    <collision>
      <origin
        xyz="0 0 0"
        rpy="0 0 0" />
      <geometry>
        <mesh
          filename="file:///home/iwatts/Documents/tang/VisionRobot/nv8arm/foxy/nv6_ws/src/moveit_resources_rrr_description/meshes_inspire/base_link.STL" />
      </geometry>
    </collision>
  </link>
  <link
    name="R_thumb_proximal_base">
    <inertial>
      <origin
        xyz="-0.0048064 0.0009382 -0.00757"
        rpy="0 0 0" />
      <mass
        value="0.0018869" />
      <inertia
        ixx="5.816E-08"
        ixy="1.4539E-08"
        ixz="4.491E-09"
        iyy="7.9161E-08"
        iyz="-1.8727E-09"
        izz="6.7433E-08" />
    </inertial>
    <visual>
      <origin
        xyz="0 0 0"
        rpy="0 0 0" />
      <geometry>
        <mesh
          filename="file:///home/iwatts/Documents/tang/VisionRobot/nv8arm/foxy/nv6_ws/src/moveit_resources_rrr_description/meshes_inspire/Link11.STL" />
      </geometry>
      <material
        name="">
        <color
          rgba="1 1 1 1" />
      </material>
    </visual>
    <collision>
      <origin
        xyz="0 0 0"
        rpy="0 0 0" />
      <geometry>
        <mesh
          filename="file:///home/iwatts/Documents/tang/VisionRobot/nv8arm/foxy/nv6_ws/src/moveit_resources_rrr_description/meshes_inspire/Link11.STL" />
      </geometry>
    </collision>
  </link>
  <joint
    name="R_thumb_proximal_yaw_joint"
    type="revolute">
    <origin
      xyz="-0.01696 -0.0691 -0.02045"
      rpy="1.5708 -1.5708 0" />
    <parent
      link="R_hand_base_link" />
    <child
      link="R_thumb_proximal_base" />
    <axis
      xyz="0 0 -1" />
    <limit
      lower="-0.1"
      upper="1.3"
      effort="10"
      velocity="0.5" />
  </joint>
  <link
    name="R_thumb_proximal">
    <inertial>
      <origin
        xyz="0.021932 0.012785 -0.0080386"
        rpy="0 0 0" />
      <mass
        value="0.0066075" />
      <inertia
        ixx="1.5686E-06"
        ixy="-7.8296E-07"
        ixz="8.9143E-10"
        iyy="1.7353E-06"
        iyz="-1.0191E-09"
        izz="2.786E-06" />
    </inertial>
    <visual>
      <origin
        xyz="0 0 0"
        rpy="0 0 0" />
      <geometry>
        <mesh
          filename="file:///home/iwatts/Documents/tang/VisionRobot/nv8arm/foxy/nv6_ws/src/moveit_resources_rrr_description/meshes_inspire/Link12.STL" />
      </geometry>
      <material
        name="">
        <color
          rgba="1 1 1 1" />
      </material>
    </visual>
    <collision>
      <origin
        xyz="0 0 0"
        rpy="0 0 0" />
      <geometry>
        <mesh
          filename="file:///home/iwatts/Documents/tang/VisionRobot/nv8arm/foxy/nv6_ws/src/moveit_resources_rrr_description/meshes_inspire/Link12.STL" />
      </geometry>
    </collision>
  </link>
  <joint
    name="R_thumb_proximal_pitch_joint"
    type="revolute">
    <origin
      xyz="-0.0088099 0.010892 -0.00925"
      rpy="1.5708 0 2.8587" />
    <parent
      link="R_thumb_proximal_base" />
    <child
      link="R_thumb_proximal" />
    <axis
      xyz="0 0 1" />
    <limit
      lower="-0.1"
      upper="0.6"
      effort="10"
      velocity="0.5" />
  </joint>
  <link
    name="R_thumb_intermediate">
    <inertial>
      <origin
        xyz="0.0095544 -0.0016282 -0.0071997"
        rpy="0 0 0" />
      <mass
        value="0.0037847" />
      <inertia
        ixx="3.6981E-07"
        ixy="-9.8581E-08"
        ixz="-4.7469E-12"
        iyy="3.2394E-07"
        iyz="1.0939E-12"
        izz="4.6531E-07" />
    </inertial>
    <visual>
      <origin
        xyz="0 0 0"
        rpy="0 0 0" />
      <geometry>
        <mesh
          filename="file:///home/iwatts/Documents/tang/VisionRobot/nv8arm/foxy/nv6_ws/src/moveit_resources_rrr_description/meshes_inspire/Link13.STL" />
      </geometry>
      <material
        name="">
        <color
          rgba="1 1 1 1" />
      </material>
    </visual>
    <collision>
      <origin
        xyz="0 0 0"
        rpy="0 0 0" />
      <geometry>
        <mesh
          filename="file:///home/iwatts/Documents/tang/VisionRobot/nv8arm/foxy/nv6_ws/src/moveit_resources_rrr_description/meshes_inspire/Link13.STL" />
      </geometry>
    </collision>
  </link>
  <joint
    name="R_thumb_intermediate_joint"
    type="revolute">
    <origin
      xyz="0.04407 0.034553 -0.0008"
      rpy="0 0 0" />
    <parent
      link="R_thumb_proximal" />
    <child
      link="R_thumb_intermediate" />
    <axis
      xyz="0 0 1" />
    <limit
      lower="0"
      upper="0.8"
      effort="10"
      velocity="0.5" />
    <mimic 
      joint="R_thumb_proximal_pitch_joint"
      multiplier="1.6"
      offset="0" />
  </joint>
  <link
    name="R_thumb_distal">
    <inertial>
      <origin
        xyz="0.0092888 0.0049529 -0.0060033"
        rpy="0 0 0" />
      <mass
        value="0.0033441" />
      <inertia
        ixx="1.3632E-07"
        ixy="-5.6788E-08"
        ixz="-9.2764E-11"
        iyy="1.4052E-07"
        iyz="-1.2283E-10"
        izz="2.0026E-07" />
    </inertial>
    <visual>
      <origin
        xyz="0 0 0"
        rpy="0 0 0" />
      <geometry>
        <mesh
          filename="file:///home/iwatts/Documents/tang/VisionRobot/nv8arm/foxy/nv6_ws/src/moveit_resources_rrr_description/meshes_inspire/Link14.STL" />
      </geometry>
      <material
        name="">
        <color
          rgba="1 1 1 1" />
      </material>
    </visual>
    <collision>
      <origin
        xyz="0 0 0"
        rpy="0 0 0" />
      <geometry>
        <mesh
          filename="file:///home/iwatts/Documents/tang/VisionRobot/nv8arm/foxy/nv6_ws/src/moveit_resources_rrr_description/meshes_inspire/Link14.STL" />
      </geometry>
    </collision>
  </link>
  <joint
    name="R_thumb_distal_joint"
    type="revolute">
    <origin
      xyz="0.020248 0.010156 -0.0012"
      rpy="0 0 0" />
    <parent
      link="R_thumb_intermediate" />
    <child
      link="R_thumb_distal" />
    <axis
      xyz="0 0 1" />
    <limit
      lower="0"
      upper="1.2"
      effort="10"
      velocity="0.5" />
    <mimic 
      joint="R_thumb_proximal_pitch_joint"
      multiplier="2.4"
      offset="0" />
  </joint>
  <link
    name="R_index_proximal_base">
    <inertial>
      <origin
        xyz="-0.0048064 0.0009382 -0.00757"
        rpy="0 0 0" />
      <mass
        value="0.0018869" />
      <inertia
        ixx="5.816E-08"
        ixy="1.4539E-08"
        ixz="4.491E-09"
        iyy="7.9161E-08"
        iyz="-1.8727E-09"
        izz="6.7433E-08" />
    </inertial>
    <visual>
      <origin
        xyz="0 0 0"
        rpy="0 0 0" />
      <geometry>
        <mesh
          filename="file:///home/iwatts/Documents/tang/VisionRobot/nv8arm/foxy/nv6_ws/src/moveit_resources_rrr_description/meshes_inspire/Link11.STL" />
      </geometry>
      <material
        name="">
        <color
          rgba="1 1 1 1" />
      </material>
    </visual>
    <collision>
      <origin
        xyz="0 0 0"
        rpy="0 0 0" />
      <geometry>
        <mesh
          filename="file:///home/iwatts/Documents/tang/VisionRobot/nv8arm/foxy/nv6_ws/src/moveit_resources_rrr_description/meshes_inspire/Link11.STL" />
      </geometry>
    </collision>
  </link>
  <joint
    name="R_index_proximal_yaw_joint"
    type="revolute">
    <origin
      xyz="-0.01696 -0.0691 0.02045"
      rpy="1.5708 -1.5708 0" />
    <parent
      link="R_hand_base_link" />
    <child
      link="R_index_proximal_base" />
    <axis
      xyz="0 0 -1" />
    <limit
      lower="-0.1"
      upper="1.3"
      effort="10"
      velocity="0.5" />
  </joint>
  <link
    name="R_index_proximal">
    <inertial>
      <origin
        xyz="0.021932 0.012785 -0.0080386"
        rpy="0 0 0" />
      <mass
        value="0.0066075" />
      <inertia
        ixx="1.5686E-06"
        ixy="-7.8296E-07"
        ixz="8.9143E-10"
        iyy="1.7353E-06"
        iyz="-1.0191E-09"
        izz="2.786E-06" />
    </inertial>
    <visual>
      <origin
        xyz="0 0 0"
        rpy="0 0 0" />
      <geometry>
        <mesh
          filename="file:///home/iwatts/Documents/tang/VisionRobot/nv8arm/foxy/nv6_ws/src/moveit_resources_rrr_description/meshes_inspire/Link12.STL" />
      </geometry>
      <material
        name="">
        <color
          rgba="1 1 1 1" />
      </material>
    </visual>
    <collision>
      <origin
        xyz="0 0 0"
        rpy="0 0 0" />
      <geometry>
        <mesh
          filename="file:///home/iwatts/Documents/tang/VisionRobot/nv8arm/foxy/nv6_ws/src/moveit_resources_rrr_description/meshes_inspire/Link12.STL" />
      </geometry>
    </collision>
  </link>
  <joint
    name="R_index_proximal_pitch_joint"
    type="revolute">
    <origin
      xyz="-0.0088099 0.010892 -0.00925"
      rpy="1.5708 0 2.8587" />
    <parent
      link="R_index_proximal_base" />
    <child
      link="R_index_proximal" />
    <axis
      xyz="0 0 1" />
    <limit
      lower="-0.1"
      upper="0.6"
      effort="10"
      velocity="0.5" />
  </joint>
  <link
    name="R_index_intermediate">
    <inertial>
      <origin
        xyz="0.0095544 -0.0016282 -0.0071997"
        rpy="0 0 0" />
      <mass
        value="0.0037847" />
      <inertia
        ixx="3.6981E-07"
        ixy="-9.8581E-08"
        ixz="-4.7469E-12"
        iyy="3.2394E-07"
        iyz="1.0939E-12"
        izz="4.6531E-07" />
    </inertial>
    <visual>
      <origin
        xyz="0 0 0"
        rpy="0 0 0" />
      <geometry>
        <mesh
          filename="file:///home/iwatts/Documents/tang/VisionRobot/nv8arm/foxy/nv6_ws/src/moveit_resources_rrr_description/meshes_inspire/Link13.STL" />
      </geometry>
      <material
        name="">
        <color
          rgba="1 1 1 1" />
      </material>
    </visual>
    <collision>
      <origin
        xyz="0 0 0"
        rpy="0 0 0" />
      <geometry>
        <mesh
          filename="file:///home/iwatts/Documents/tang/VisionRobot/nv8arm/foxy/nv6_ws/src/moveit_resources_rrr_description/meshes_inspire/Link13.STL" />
      </geometry>
    </collision>
  </link>
  <joint
    name="R_index_intermediate_joint"
    type="revolute">
    <origin
      xyz="0.04407 0.034553 -0.0008"
      rpy="0 0 0" />
    <parent
      link="R_index_proximal" />
    <child
      link="R_index_intermediate" />
    <axis
      xyz="0 0 1" />
    <limit
      lower="0"
      upper="0.8"
      effort="10"
      velocity="0.5" />
    <mimic 
      joint="R_index_proximal_pitch_joint"
      multiplier="1.6"
      offset="0" />
  </joint>
  <link
    name="R_index_distal">
    <inertial>
      <origin
        xyz="0.0092888 0.0049529 -0.0060033"
        rpy="0 0 0" />
      <mass
        value="0.0033441" />
      <inertia
        ixx="1.3632E-07"
        ixy="-5.6788E-08"
        ixz="-9.2764E-11"
        iyy="1.4052E-07"
        iyz="-1.2283E-10"
        izz="2.0026E-07" />
    </inertial>
    <visual>
      <origin
        xyz="0 0 0"
        rpy="0 0 0" />
      <geometry>
        <mesh
          filename="file:///home/iwatts/Documents/tang/VisionRobot/nv8arm/foxy/nv6_ws/src/moveit_resources_rrr_description/meshes_inspire/Link14.STL" />
      </geometry>
      <material
        name="">
        <color
          rgba="1 1 1 1" />
      </material>
    </visual>
    <collision>
      <origin
        xyz="0 0 0"
        rpy="0 0 0" />
      <geometry>
        <mesh
          filename="file:///home/iwatts/Documents/tang/VisionRobot/nv8arm/foxy/nv6_ws/src/moveit_resources_rrr_description/meshes_inspire/Link14.STL" />
      </geometry>
    </collision>
  </link>
  <joint
    name="R_index_distal_joint"
    type="revolute">
    <origin
      xyz="0.020248 0.010156 -0.0012"
      rpy="0 0 0" />
    <parent
      link="R_index_intermediate" />
    <child
      link="R_index_distal" />
    <axis
      xyz="0 0 1" />
    <limit
      lower="0"
      upper="1.2"
      effort="10"
      velocity="0.5" />
    <mimic 
      joint="R_index_proximal_pitch_joint"
      multiplier="2.4"
      offset="0" />
  </joint>
</robot>
