<?xml version="1.0" ?>
<!-- =================================================================================== -->
<!-- |    This document was autogenerated by xacro from rrr_arm.xacro                  | -->
<!-- |    EDITING THIS FILE BY HAND IS NOT RECOMMENDED                                 | -->
<!-- =================================================================================== -->
<!-- Make the namespace of the robot-->
<robot name="rrr_arm">
  <!--finger radius/length-->
  <!--finger length-->
  <!--Define Rviz colors-->
  </joint>
  <!--base_link-->
  <link name="base_link">
    <inertial>
      <origin rpy="0 0 0" xyz="0 0 0.075"/>
      <mass value="20"/>
      <inertia ixx="0.10416666666666667" ixy="0.0" ixz="0.0" iyy="0.10416666666666667" iyz="0.0" izz="0.13333333333333336"/>
    </inertial>
    <visual>
      <origin rpy="0.0 0.0 0.0" xyz="0.0 0.0 0.075"/>
      <geometry>
        <mesh filename="package://moveit_resources_panda_description/meshes/visual/link4.dae" />
      </geometry>
    </visual>
    <collision>
      <origin rpy="0.0 0.0 0.0" xyz="0.0 0.0 0.075"/>
      <geometry>
      </geometry>
    </collision>
  </link>
  <joint name="joint_1" type="revolute">
    <origin rpy="0.0 0.0 0.0" xyz="0.0 0.0 0.15"/>
    <parent link="base_link"/>
    <child link="link_1"/>
    <axis xyz="0.0 0.0 1"/>
    <limit effort="300.0" lower="0.0" upper="6.28318" velocity="1.0"/>
  </joint>
  <!--=============================================================================-->
  <!--link_1-->
  <link name="link_1">
    <inertial>
      <origin rpy="0 0 0" xyz="0 0 0.2"/>
      <mass value="5"/>
      <inertia ixx="0.07083333333333336" ixy="0.0" ixz="0.0" iyy="0.07083333333333336" iyz="0.0" izz="0.008333333333333335"/>
    </inertial>
    <visual>
      <origin rpy="0.0 0.0 0.0" xyz="0.0 0.0 0.2"/>
      <geometry>
        <mesh filename="package://moveit_resources_panda_description/meshes/visual/link4.dae" />
      </geometry>
    </visual>
    <collision>
      <origin rpy="0.0 0.0 0.0" xyz="0.0 0.0 0.2"/>
      <geometry>
        <mesh filename="package://moveit_resources_panda_description/meshes/visual/link4.dae" />
      </geometry>      
    </collision>
  </link>
  </link>
  <!-- ros_control plugin -->
  </robot>

